Workbook
Name NativeTimeline_Invoice_Date: #N/A
Name Slicer_Beverage_Brand: #N/A
Name Slicer_Region: #N/A
Name Slicer_Retailer: #N/A

Sheet Data
B2: Key American Coca-Cola Retailers
B3: Beverage Sales & Operating Margin 2021
A5: Column1 | B5: Retailer | C5: Retailer ID | D5: Invoice Date | E5: Region | F5: State | G5: City | H5: Beverage Brand | I5: Price per Unit | J5: Units Sold | K5: Total Sales | L5: Operating Profit | M5: Operating Margin
B6: Sodapop | C6: 1185732 | D6: 44210 | E6: Northeast | F6: New York | G6: New York | H6: Coca-Cola | I6: 0.5 | J6: 12000 | K6: =I6*J6 -> 6000 | L6: =K6*M6 -> 3000 | M6: 0.5
B7: Sodapop | C7: 1185732 | D7: 44210 | E7: Northeast | F7: New York | G7: New York | H7: Diet Coke | I7: 0.5 | J7: 10000 | K7: =I7*J7 -> 5000 | L7: =K7*M7 -> 1500 | M7: 0.3
B8: Sodapop | C8: 1185732 | D8: 44210 | E8: Northeast | F8: New York | G8: New York | H8: Sprite | I8: 0.4 | J8: 10000 | K8: =I8*J8 -> 4000 | L8: =K8*M8 -> 1400 | M8: 0.35
B9: Sodapop | C9: 1185732 | D9: 44210 | E9: Northeast | F9: New York | G9: New York | H9: Fanta | I9: 0.45 | J9: 8500 | K9: =I9*J9 -> 3825 | L9: =K9*M9 -> 1338.75 | M9: 0.35
B10: Sodapop | C10: 1185732 | D10: 44210 | E10: Northeast | F10: New York | G10: New York | H10: Powerade | I10: 0.6 | J10: 9000 | K10: =I10*J10 -> 5400 | L10: =K10*M10 -> 1620 | M10: 0.3
B11: Sodapop | C11: 1185732 | D11: 44210 | E11: Northeast | F11: New York | G11: New York | H11: Dasani Water | I11: 0.5 | J11: 10000 | K11: =I11*J11 -> 5000 | L11: =K11*M11 -> 1250 | M11: 0.25
B12: Sodapop | C12: 1185732 | D12: 44239 | E12: Northeast | F12: New York | G12: New York | H12: Coca-Cola | I12: 0.5 | J12: 12500 | K12: =I12*J12 -> 6250 | L12: =K12*M12 -> 3125 | M12: 0.5
B13: Sodapop | C13: 1185732 | D13: 44239 | E13: Northeast | F13: New York | G13: New York | H13: Diet Coke | I13: 0.5 | J13: 9000 | K13: =I13*J13 -> 4500 | L13: =K13*M13 -> 1350 | M13: 0.3
B14: Sodapop | C14: 1185732 | D14: 44239 | E14: Northeast | F14: New York | G14: New York | H14: Sprite | I14: 0.4 | J14: 9500 | K14: =I14*J14 -> 3800 | L14: =K14*M14 -> 1330 | M14: 0.35
B15: Sodapop | C15: 1185732 | D15: 44239 | E15: Northeast | F15: New York | G15: New York | H15: Fanta | I15: 0.45 | J15: 8250 | K15: =I15*J15 -> 3712.5 | L15: =K15*M15 -> 1299.375 | M15: 0.35
B16: Sodapop | C16: 1185732 | D16: 44239 | E16: Northeast | F16: New York | G16: New York | H16: Powerade | I16: 0.6 | J16: 9000 | K16: =I16*J16 -> 5400 | L16: =K16*M16 -> 1620 | M16: 0.3
B17: Sodapop | C17: 1185732 | D17: 44239 | E17: Northeast | F17: New York | G17: New York | H17: Dasani Water | I17: 0.5 | J17: 10000 | K17: =I17*J17 -> 5000 | L17: =K17*M17 -> 1250 | M17: 0.25
... B509: Sodapop | C509: 1185732 | D509: 44533 | E509: Northeast | F509: Pennsylvania | G509: Philadelphia | H509: Dasani Water | I509: 0.75 | J509: 2750 | K509: =I509*J509 -> 2062.5 | L509: =K509*M509 -> 618.75 | M509: 0.3
A510: x | B510: FizzySip | C510: 1128299 | D510: 44211 | E510: West | F510: Nevada | G510: Las Vegas | H510: Coca-Cola | I510: 0.35 | J510: 4500 | K510: =I510*J510 -> 1575 | L510: =K510*M510 -> 630 | M510: 0.4
B511: FizzySip | C511: 1128299 | D511: 44211 | E511: West | F511: Nevada | G511: Las Vegas | H511: Diet Coke | I511: 0.45 | J511: 4500 | K511: =I511*J511 -> 2025 | L511: =K511*M511 -> 506.25 | M511: 0.25
B512: FizzySip | C512: 1128299 | D512: 44211 | E512: West | F512: Nevada | G512: Las Vegas | H512: Sprite | I512: 0.45 | J512: 4500 | K512: =I512*J512 -> 2025 | L512: =K512*M512 -> 810 | M512: 0.4
B513: FizzySip | C513: 1128299 | D513: 44211 | E513: West | F513: Nevada | G513: Las Vegas | H513: Fanta | I513: 0.45 | J513: 3000 | K513: =I513*J513 -> 1350 | L513: =K513*M513 -> 472.5 | M513: 0.35
B514: FizzySip | C514: 1128299 | D514: 44211 | E514: West | F514: Nevada | G514: Las Vegas | H514: Powerade | I514: 0.5 | J514: 2500 | K514: =I514*J514 -> 1250 | L514: =K514*M514 -> 687.5 | M514: 0.55
B515: FizzySip | C515: 1128299 | D515: 44211 | E515: West | F515: Nevada | G515: Las Vegas | H515: Dasani Water | I515: 0.45 | J515: 4750 | K515: =I515*J515 -> 2137.5 | L515: =K515*M515 -> 427.5 | M515: 0.2
B516: FizzySip | C516: 1128299 | D516: 44242 | E516: West | F516: Nevada | G516: Las Vegas | H516: Coca-Cola | I516: 0.35 | J516: 5250 | K516: =I516*J516 -> 1837.5 | L516: =K516*M516 -> 735 | M516: 0.4
B517: FizzySip | C517: 1128299 | D517: 44242 | E517: West | F517: Nevada | G517: Las Vegas | H517: Diet Coke | I517: 0.45 | J517: 4250 | K517: =I517*J517 -> 1912.5 | L517: =K517*M517 -> 478.125 | M517: 0.25
B518: FizzySip | C518: 1128299 | D518: 44242 | E518: West | F518: Nevada | G518: Las Vegas | H518: Sprite | I518: 0.45 | J518: 4250 | K518: =I518*J518 -> 1912.5 | L518: =K518*M518 -> 765 | M518: 0.4
B519: FizzySip | C519: 1128299 | D519: 44242 | E519: West | F519: Nevada | G519: Las Vegas | H519: Fanta | I519: 0.45 | J519: 2750 | K519: =I519*J519 -> 1237.5 | L519: =K519*M519 -> 433.125 | M519: 0.35
B520: FizzySip | C520: 1128299 | D520: 44242 | E520: West | F520: Nevada | G520: Las Vegas | H520: Powerade | I520: 0.5 | J520: 2000 | K520: =I520*J520 -> 1000 | L520: =K520*M520 -> 550 | M520: 0.55
B521: FizzySip | C521: 1128299 | D521: 44242 | E521: West | F521: Nevada | G521: Las Vegas | H521: Dasani Water | I521: 0.45 | J521: 4000 | K521: =I521*J521 -> 1800 | L521: =K521*M521 -> 360 | M521: 0.2
B522: FizzySip | C522: 1128299 | D522: 44269 | E522: West | F522: Nevada | G522: Las Vegas | H522: Coca-Cola | I522: 0.45 | J522: 5500 | K522: =I522*J522 -> 2475 | L522: =K522*M522 -> 990 | M522: 0.4
... B581: FizzySip | C581: 1128299 | D581: 44544 | E581: West | F581: Nevada | G581: Las Vegas | H581: Dasani Water | I581: 0.75 | J581: 5000 | K581: =I581*J581 -> 3750 | L581: =K581*M581 -> 562.5 | M581: 0.15
A582: x | B582: FizzySip | C582: 1128299 | D582: 44201 | E582: West | F582: Colorado | G582: Denver | H582: Coca-Cola | I582: 0.3 | J582: 4250 | K582: =I582*J582 -> 1275 | L582: =K582*M582 -> 446.25 | M582: 0.35
B583: FizzySip | C583: 1128299 | D583: 44201 | E583: West | F583: Colorado | G583: Denver | H583: Diet Coke | I583: 0.4 | J583: 4250 | K583: =I583*J583 -> 1700 | L583: =K583*M583 -> 340 | M583: 0.2
B584: FizzySip | C584: 1128299 | D584: 44201 | E584: West | F584: Colorado | G584: Denver | H584: Sprite | I584: 0.4 | J584: 4250 | K584: =I584*J584 -> 1700 | L584: =K584*M584 -> 595 | M584: 0.35
B585: FizzySip | C585: 1128299 | D585: 44201 | E585: West | F585: Colorado | G585: Denver | H585: Fanta | I585: 0.4 | J585: 2750 | K585: =I585*J585 -> 1100 | L585: =K585*M585 -> 330 | M585: 0.3
B586: FizzySip | C586: 1128299 | D586: 44201 | E586: West | F586: Colorado | G586: Denver | H586: Powerade | I586: 0.45 | J586: 2250 | K586: =I586*J586 -> 1012.5 | L586: =K586*M586 -> 506.25 | M586: 0.5
B587: FizzySip | C587: 1128299 | D587: 44201 | E587: West | F587: Colorado | G587: Denver | H587: Dasani Water | I587: 0.4 | J587: 4750 | K587: =I587*J587 -> 1900 | L587: =K587*M587 -> 285 | M587: 0.15
B588: FizzySip | C588: 1128299 | D588: 44232 | E588: West | F588: Colorado | G588: Denver | H588: Coca-Cola | I588: 0.3 | J588: 5250 | K588: =I588*J588 -> 1575 | L588: =K588*M588 -> 551.25 | M588: 0.35
B589: FizzySip | C589: 1128299 | D589: 44232 | E589: West | F589: Colorado | G589: Denver | H589: Diet Coke | I589: 0.4 | J589: 4250 | K589: =I589*J589 -> 1700 | L589: =K589*M589 -> 340 | M589: 0.2
B590: FizzySip | C590: 1128299 | D590: 44232 | E590: West | F590: Colorado | G590: Denver | H590: Sprite | I590: 0.4 | J590: 4250 | K590: =I590*J590 -> 1700 | L590: =K590*M590 -> 595 | M590: 0.35
B591: FizzySip | C591: 1128299 | D591: 44232 | E591: West | F591: Colorado | G591: Denver | H591: Fanta | I591: 0.4 | J591: 2750 | K591: =I591*J591 -> 1100 | L591: =K591*M591 -> 330 | M591: 0.3
...

Sheet Piviot Tables
A3: Sum of Total Sales | B3: Sum of Units Sold | C3: Sum of Operating Profit | D3: Average of Operating Margin
A4: 8684027.5 | B4: 17148250 | C4: 3173631.9 | D4: 0.36310442
A9: Row Labels | B9: Sum of Total Sales
A10: Jan | B10: 510750
A11: Feb | B11: 484975
A12: Mar | B12: 483530
A13: Apr | B13: 494887.5
A14: May | B14: 673572.5
A15: Jun | B15: 903837.5
A16: Jul | B16: 1041437.5
A17: Aug | B17: 945275
A18: Sep | B18: 681000
A19: Oct | B19: 623375
A20: Nov | B20: 795612.5
A21: Dec | B21: 1045775
A22: Grand Total | B22: 8684027.5
A27: Row Labels | B27: Sum of Units Sold | D27: State | E27: Unit Sold
A28: Alabama | B28: 408500 | D28: =A28 -> Alabama | E28: =B28 -> 408500
A29: Alaska | B29: 312250 | D29: =A29 -> Alaska | E29: =B29 -> 312250
A30: Arizona | B30: 331500 | D30: =A30 -> Arizona | E30: =B30 -> 331500
A31: Arkansas | B31: 255350 | D31: =A31 -> Arkansas | E31: =B31 -> 255350
A32: California | B32: 1037250 | D32: =A32 -> California | E32: =B32 -> 1037250
A33: Colorado | B33: 324250 | D33: =A33 -> Colorado | E33: =B33 -> 324250
A34: Connecticut | B34: 169600 | D34: =A34 -> Connecticut | E34: =B34 -> 169600
A35: Delaware | B35: 205600 | D35: =A35 -> Delaware | E35: =B35 -> 205600
A36: Florida | B36: 1051700 | D36: =A36 -> Florida | E36: =B36 -> 1051700
A37: Georgia | B37: 579350 | D37: =A37 -> Georgia | E37: =B37 -> 579350
A38: Hawaii | B38: 353500 | D38: =A38 -> Hawaii | E38: =B38 -> 353500
A39: Idaho | B39: 288250 | D39: =A39 -> Idaho | E39: =B39 -> 288250
... A77: Wyoming | B77: 310750 | D77: =A77 -> Wyoming | E77: =B77 -> 310750
A78: Grand Total | B78: 17148250

Sheet Dashboard
D2: Key American Retailers | L2: Sum Of Total Sales | N2: Sum Of Units Sold | P2: Sum Of Operating Profit | R2: Average of Margin
L3: =GETPIVOTDATA("Sum of Total Sales",'Piviot Tables'!$A$3) -> 8684027.5 | N3: =GETPIVOTDATA("Sum of Units Sold",'Piviot Tables'!$A$3) -> 17148250 | P3: =GETPIVOTDATA("Sum of Operating Profit",'Piviot Tables'!$A$3) -> 3173631.9 | R3: =GETPIVOTDATA("Average of Operating Margin",'Piviot Tables'!$A$3) -> 0.36310442
